<?xml version="1.0" encoding="UTF-8"?>
<sdf version='1.9'>
<model name='x500'>
	<pose>-4 2 0.2 0 0 0</pose>
	<self_collide>false</self_collide>
	<static>false</static>
	<link name="base_link">
		<inertial>
			<mass> 1.9 </mass>
			<inertia>
				<ixx>0.027608</ixx>
				<ixy>-0.000018</ixy>
				<ixz>-0.00001</ixz>
				<iyy>0.035319</iyy>
				<iyz>-0.000415</iyz>
				<izz>0.055487</izz>
			</inertia>
		</inertial>
		<gravity>true</gravity>
		<velocity_decay/>
		<visual name="base_link_visual">
			<pose>0 0 0 0 0 -1.57</pose>
			<geometry>
				<mesh>
					<uri>model://x500/meshes/DRONE_MONTAJ.STL</uri>
				</mesh>
			</geometry>
			<material>
				<ambient>0.5 0.75 0 1</ambient>
				<diffuse>0.7 0.9 0 1</diffuse>
				<emissive>0.1 0 0.1 1</emissive>
			</material>
		</visual>
		<collision name="base_link_collision_0">
			<pose>0.02 0 -0.025 0 0 0</pose>
			<geometry>
				<box>
					<size>0.42 0.337 0.2</size>
				</box>
			</geometry>
			<surface>
				<contact>
					<ode>
					<min_depth>0.001</min_depth>
					<max_vel>0</max_vel>
					</ode>
				</contact>
				<friction>
					<ode/>
				</friction>
			</surface>
		</collision>

		<light name="left_light_source" type="spot">
			<visualize>false</visualize>
			<pose>0.14 0 -0.003 0 -1.57 0</pose>
			<attenuation>
				<range>10</range>
				<linear>0</linear>
				<constant>0.1</constant>
				<quadratic>0.0025</quadratic>
			</attenuation>
			<diffuse>0.8 0.8 0.5 1</diffuse>
			<specular>0.8 0.8 0.5 1</specular>
			<spot>
				<inner_angle>1</inner_angle>
				<outer_angle>1.1</outer_angle>
				<falloff>1</falloff>
			</spot>
			<direction>0 0 -1</direction>
			<cast_shadows>1</cast_shadows>
		</light>

		<sensor name="air_pressure_sensor" type="air_pressure">
			<always_on>1</always_on>
			<update_rate>50</update_rate>
			<air_pressure>
				<pressure>
					<noise type="gaussian">
					<mean>0</mean>
					<stddev>0.01</stddev>
					</noise>
				</pressure>
			</air_pressure>
		</sensor>

		<sensor name="imu_sensor" type="imu">
			<always_on>1</always_on>
			<update_rate>250</update_rate>
		</sensor>

		<sensor name="Vision_camera" type="camera">
			<pose>0.1235 0 -0.003 0 0 0</pose>
			<topic>camera_vision</topic>
			<camera>
				<horizontal_fov>1.3</horizontal_fov>
				<image>
					<width>480</width>
					<height>480</height>
				</image>
			</camera>
			<always_on>1</always_on>
			<update_rate>35</update_rate>
			<visualize>true</visualize>
		</sensor>

		<!-- <sensor name="out_camera" type="camera">
			<pose>-1.2 0 0.25 0 0.5 0</pose>
			<topic>out_camera</topic>
			<camera>
				<horizontal_fov>1.57</horizontal_fov>
				<image>
					<width>720</width>
					<height>360</height>
				</image>
			</camera>
			<always_on>1</always_on>
			<update_rate>20</update_rate>
			<visualize>true</visualize>
		</sensor> -->

		<!-- <sensor name="front_laser" type="gpu_ray">
			<pose>0.055 0.058 -0.043 0 0 1.57</pose>
			<update_rate>4</update_rate>
			<topic>lidar</topic>
			<lidar>
				<scan>
					<horizontal>
						<samples>8</samples>
						<resolution>1</resolution>
						<min_angle>-0.38</min_angle>
						<max_angle>0.38</max_angle>
					</horizontal>
					<vertical>
						<samples>8</samples>
						<resolution>1</resolution>
						<min_angle>-0.38</min_angle>
						<max_angle>0.38</max_angle>                           
					</vertical>
				</scan>
				<range>
					<min>0.01</min>
					<max>2.0</max>
					<resolution>0.01</resolution>
				</range>
				<noise>
					<type>gaussian</type>
					<mean>0</mean>
					<stddev>0.01</stddev>
				</noise>
			</lidar>
		</sensor> -->

		<sensor name="depth_camera_on" type="depth_camera">
			<pose>0.14 0.0 -0.045 0 0 0</pose>
			<update_rate>4</update_rate>
			<topic>depth_camera_on</topic>
			<visualize>true</visualize>
			<camera>
				<horizontal_fov>0.785</horizontal_fov>
				<image>
					<width>8</width>
					<height>8</height>
					<format>R_FLOAT32</format>
				</image>
				<clip>
					<near>0.05</near>
					<far>2.0</far>
				</clip>
				<noise>
					<type>gaussian</type>
					<mean>0</mean>
					<stddev>0.005</stddev>
				</noise>
			</camera>
		</sensor>

		<sensor name="depth_camera_on_sag" type="depth_camera">
			<pose>0.11 -0.052 -0.041 0 0 -0.78</pose>
			<update_rate>4</update_rate>
			<topic>depth_camera_on_sag</topic>
			<visualize>true</visualize>
			<camera>
				<horizontal_fov>0.785</horizontal_fov>
				<image>
					<width>4</width>
					<height>4</height>
					<format>R_FLOAT32</format>
				</image>
				<clip>
					<near>0.05</near>
					<far>2.0</far>
				</clip>
				<noise>
					<type>gaussian</type>
					<mean>0</mean>
					<stddev>0.01</stddev>
				</noise>
			</camera>
		</sensor>

		<sensor name="depth_camera_on_sol" type="depth_camera">
			<pose>0.11 0.052 -0.041 0 0 0.78</pose>
			<update_rate>4</update_rate>
			<topic>depth_camera_on_sol</topic>
			<visualize>true</visualize>
			<camera>
				<horizontal_fov>0.785</horizontal_fov>
				<image>
					<width>4</width>
					<height>4</height>
					<format>R_FLOAT32</format>
				</image>
				<clip>
					<near>0.05</near>
					<far>2.0</far>
				</clip>
				<noise>
					<type>gaussian</type>
					<mean>0</mean>
					<stddev>0.01</stddev>
				</noise>
			</camera>
		</sensor>

		<sensor name="depth_camera_sol" type="depth_camera">
			<pose>0.058 0.058 -0.041 0 0 1.57</pose>
			<update_rate>4</update_rate>
			<topic>depth_camera_sol</topic>
			<visualize>true</visualize>
			<camera>
				<horizontal_fov>0.785</horizontal_fov>
				<image>
					<format>R_FLOAT32</format>
					<width>4</width>
					<height>4</height>
				</image>
				<clip>
					<near>0.05</near>
					<far>2.0</far>
				</clip>
				<noise>
					<type>gaussian</type>
					<mean>0</mean>
					<stddev>0.01</stddev>
				</noise>
			</camera>
		</sensor>

		<sensor name="depth_camera_sag" type="depth_camera">
			<pose>0.058 -0.058 -0.041 0 0 -1.57</pose>
			<update_rate>4</update_rate>
			<topic>depth_camera_sag</topic>
			<visualize>true</visualize>
			<camera>
				<horizontal_fov>0.785</horizontal_fov>
				<image>
					<format>R_FLOAT32</format>
					<width>4</width>
					<height>4</height>
				</image>
				<clip>
					<near>0.05</near>
					<far>2.0</far>
				</clip>
				<noise>
					<type>gaussian</type>
					<mean>0</mean>
					<stddev>0.01</stddev>
				</noise>
			</camera>
		</sensor>

		<sensor name="depth_camera_arka" type="depth_camera">
			<pose>-0.075 -0.035 -0.040 0 0 3.14</pose>
			<update_rate>4</update_rate>
			<topic>depth_camera_arka</topic>
			<visualize>true</visualize>
			<camera>
				<horizontal_fov>0.785</horizontal_fov>
				<image>
					<format>R_FLOAT32</format>
					<width>4</width>
					<height>4</height>
				</image>
				<clip>
					<near>0.05</near>
					<far>2.0</far>
				</clip>
				<noise>
					<type>gaussian</type>
					<mean>0</mean>
					<stddev>0.01</stddev>
				</noise>
			</camera>
		</sensor>   

		<sensor name="depth_camera_ust" type="depth_camera">
			<pose>0.06 0.015 0.02 0 -1.57 0</pose>
			<update_rate>4</update_rate>
			<topic>depth_camera_ust</topic>
			<visualize>true</visualize>
			<camera>
				<horizontal_fov>0.785</horizontal_fov>
				<image>
					<format>R_FLOAT32</format>
					<width>4</width>
					<height>4</height>
				</image>
				<clip>
					<near>0.05</near>
					<far>2.0</far>
				</clip>
				<noise>
					<type>gaussian</type>
					<mean>0</mean>
					<stddev>0.01</stddev>
				</noise>
			</camera>
		</sensor>

		<sensor name="depth_camera_alt" type="depth_camera">
			<pose>0.115 -0.026 -0.06 0 1.57 0</pose>
			<update_rate>4</update_rate>
			<topic>depth_camera_alt</topic>
			<visualize>true</visualize>
			<camera>
				<horizontal_fov>0.785</horizontal_fov>
				<image>
					<format>R_FLOAT32</format>
					<width>4</width>
					<height>4</height>
				</image>
				<clip>
					<near>0.01</near>
					<far>3.0</far>
				</clip>
				<noise>
					<type>gaussian</type>
					<mean>0</mean>
					<stddev>0.01</stddev>
				</noise>
			</camera>
		</sensor>
	</link>
  <link name="KAMERA">
      <pose> 0.1235 0 -0.003 0 0 -1.57 </pose>
      <inertial>
    <pose> 0 0 0 0 0 0 </pose>
    <mass> 0.022401</mass>
    <inertia>
      <ixx>4.252E-06</ixx>
      <ixy>-1.544E-10</ixy>
      <ixz>-2.1481E-07</ixz>
      <iyy>5.7219E-06</iyy>
      <iyz>-1.0484E-09</iyz>
      <izz>6.2901E-06</izz>
    </inertia>
      </inertial>
      <visual name= "kamera_visual">
        <pose> 0 0 0 0 0 0 </pose>
        <geometry>
          <mesh>
            <uri>model://x500/meshes/KAMERA_MONTAJ.STL</uri>
          </mesh>
        </geometry>
        <material>
          <ambient>0.2 0.2 0 1</ambient>
          <diffuse>0.2 0.2 0 1</diffuse>
          <emissive>0.1 0 0.1 1</emissive>
        </material>
      </visual>
  </link>
    <joint name="J-KAMERA" type="revolute">
        <parent>base_link</parent>
        <child>KAMERA</child>
        <axis>
          <xyz> 1 0 0 </xyz>
          <limit>
            <lower>-1e+16</lower>
            <upper>1e+16</upper>
          </limit>
          <dynamics>
            <spring_reference>0</spring_reference>
            <spring_stiffness>0</spring_stiffness>
          </dynamics>
          <!-- <use_parent_model_frame>1</use_parent_model_frame> -->
        </axis>
    </joint>
    <link name="rotor_0">
      <gravity>true</gravity>
      <self_collide>false</self_collide>
      <velocity_decay/>
      <pose>0.09 -0.105 0 0 0 0</pose>
      <inertial>
          <mass>0.016076923076923075</mass>
          <inertia>
            <ixx>3.8464910483993325e-07</ixx>
            <iyy>2.6115851691700804e-05</iyy>
            <izz>2.649858234714004e-05</izz>
          </inertia>
        </inertial>
      <visual name="rotor_0_visual">
        <pose>0 0 0 0 0 0</pose>
        <geometry>
          <mesh>
            <scale>0.8461538461538461 0.8461538461538461 0.8461538461538461</scale>
            <uri>model://x500/meshes/SOL_ON_PERVANE.STL</uri>
          </mesh>
        </geometry>
        <material>
          <script>
            <name>Gazebo/DarkGrey</name>
            <uri>file://media/materials/scripts/gazebo.material</uri>
          </script>
        </material>
      </visual>
      <!-- <collision name="rotor_0_collision">
        <pose>0 0 0 0 0 0 </pose>
        <geometry>
          <box>
            <size>0.1192307692307692 0.016923076923076923 0.0008461538461538462</size>
          </box>
        </geometry>
        <surface>
          <contact>
            <ode>
              <min_depth>0.001</min_depth>
              <max_vel>0</max_vel>
            </ode>
          </contact>
          <friction>
            <ode/>
          </friction>
        </surface>
      </collision> -->
    </link>
    <joint name="rotor_0_joint" type="revolute">
      <parent>base_link</parent>
      <child>rotor_0</child>
      <axis>
        <xyz>0 0 1</xyz>
        <limit>
          <lower>-1e+16</lower>
          <upper>1e+16</upper>
        </limit>
        <dynamics>
          <spring_reference>0</spring_reference>
          <spring_stiffness>0</spring_stiffness>
        </dynamics>
      </axis>
    </joint>
    <link name="rotor_1">
      <gravity>true</gravity>
      <self_collide>false</self_collide>
      <velocity_decay/>
      <pose>-0.09 0.105 0 0 0 0</pose>
      <inertial>
          <mass>0.016076923076923075</mass>
          <inertia>
            <ixx>3.8464910483993325e-07</ixx>
            <iyy>2.6115851691700804e-05</iyy>
            <izz>2.649858234714004e-05</izz>
          </inertia>
        </inertial>
      <visual name="rotor_1_visual">
        <pose>0 0 0 0 0 0</pose>
        <geometry>
          <mesh>
            <scale>0.8461538461538461 0.8461538461538461 0.8461538461538461</scale>
            <uri>model://x500/meshes/SOL_ON_PERVANE.STL</uri>
          </mesh>
        </geometry>
        <material>
          <script>
            <name>Gazebo/DarkGrey</name>
            <uri>file://media/materials/scripts/gazebo.material</uri>
          </script>
        </material>
      </visual>
      <!-- <collision name="rotor_1_collision">
        <pose>0 0 0 0 0 0 </pose>
        <geometry>
          <box>
            <size>0.1192307692307692 0.016923076923076923 0.0008461538461538462</size>
          </box>
        </geometry>
        <surface>
          <contact>
            <ode>
              <min_depth>0.001</min_depth>
              <max_vel>0</max_vel>
            </ode>
          </contact>
          <friction>
            <ode/>
          </friction>
        </surface>
      </collision> -->
    </link>
    <joint name="rotor_1_joint" type="revolute">
      <parent>base_link</parent>
      <child>rotor_1</child>
      <axis>
        <xyz>0 0 1</xyz>
        <limit>
          <lower>-1e+16</lower>
          <upper>1e+16</upper>
        </limit>
        <dynamics>
          <spring_reference>0</spring_reference>
          <spring_stiffness>0</spring_stiffness>
        </dynamics>
      </axis>
    </joint>
    <link name="rotor_2">
      <gravity>true</gravity>
      <self_collide>false</self_collide>
      <velocity_decay/>
      <pose>0.09 0.105 0 0 0 0</pose>
      <inertial>
          <mass>0.016076923076923075</mass>
          <inertia>
            <ixx>3.8464910483993325e-07</ixx>
            <iyy>2.6115851691700804e-05</iyy>
            <izz>2.649858234714004e-05</izz>
          </inertia>
        </inertial>
      <visual name="rotor_2_visual">
        <pose>0 0 0 0 0 0</pose>
        <geometry>
          <mesh>
            <scale>0.8461538461538461 0.8461538461538461 0.8461538461538461</scale>
            <uri>model://x500/meshes/SAG_ON_PERVANE.STL</uri>
          </mesh>
        </geometry>
        <material>
          <script>
            <name>Gazebo/DarkGrey</name>
            <uri>file://media/materials/scripts/gazebo.material</uri>
          </script>
        </material>
      </visual>
      <!-- <collision name="rotor_2_collision">
        <pose>0 0 0 0 0 0 </pose>
        <geometry>
          <box>
            <size>0.1192307692307692 0.016923076923076923 0.0008461538461538462</size>
          </box>
        </geometry>
        <surface>
          <contact>
            <ode>
              <min_depth>0.001</min_depth>
              <max_vel>0</max_vel>
            </ode>
          </contact>
          <friction>
            <ode/>
          </friction>
        </surface>
      </collision> -->
    </link>
    <joint name="rotor_2_joint" type="revolute">
      <parent>base_link</parent>
      <child>rotor_2</child>
      <axis>
        <xyz>0 0 1</xyz>
        <limit>
          <lower>-1e+16</lower>
          <upper>1e+16</upper>
        </limit>
        <dynamics>
          <spring_reference>0</spring_reference>
          <spring_stiffness>0</spring_stiffness>
        </dynamics>
      </axis>
    </joint>
    <link name="rotor_3">
      <gravity>true</gravity>
      <self_collide>false</self_collide>
      <velocity_decay/>
      <pose>-0.09 -0.105 0 0 0 0</pose>
      <inertial>
          <mass>0.016076923076923075</mass>
          <inertia>
            <ixx>3.8464910483993325e-07</ixx>
            <iyy>2.6115851691700804e-05</iyy>
            <izz>2.649858234714004e-05</izz>
          </inertia>
        </inertial>
      <visual name="rotor_3_visual">
        <pose>0 0 0 0 0 0</pose>
        <geometry>
          <mesh>
            <scale>0.8461538461538461 0.8461538461538461 0.8461538461538461</scale>
            <uri>model://x500/meshes/SAG_ON_PERVANE.STL</uri>
          </mesh>
        </geometry>
        <material>
          <script>
            <name>Gazebo/DarkGrey</name>
            <uri>file://media/materials/scripts/gazebo.material</uri>
          </script>
        </material>
      </visual>
      <!-- <collision name="rotor_3_collision">
        <pose>0 0 0 0 0 0 </pose>
        <geometry>
          <box>
            <size>0.1192307692307692 0.016923076923076923 0.0008461538461538462</size>
          </box>
        </geometry>
        <surface>
          <contact>
            <ode>
              <min_depth>0.001</min_depth>
              <max_vel>0</max_vel>
            </ode>
          </contact>
          <friction>
            <ode/>
          </friction>
        </surface>
      </collision> -->
    </link>
    <joint name="rotor_3_joint" type="revolute">
      <parent>base_link</parent>
      <child>rotor_3</child>
      <axis>
        <xyz>0 0 1</xyz>
        <limit>
          <lower>-1e+16</lower>
          <upper>1e+16</upper>
        </limit>
        <dynamics>
          <spring_reference>0</spring_reference>
          <spring_stiffness>0</spring_stiffness>
        </dynamics>
      </axis>
    </joint>
   <plugin filename="gz-sim-multicopter-motor-model-system" name="gz::sim::systems::MulticopterMotorModel">
      <jointName>rotor_0_joint</jointName>
      <linkName>rotor_0</linkName>
      <turningDirection>ccw</turningDirection>
      <timeConstantUp>0.0125</timeConstantUp>
      <timeConstantDown>0.025</timeConstantDown>
      <maxRotVelocity>1000.0</maxRotVelocity>
      <motorConstant>8.54858e-06</motorConstant>
      <momentConstant>0.016</momentConstant>
      <commandSubTopic>command/motor_speed</commandSubTopic>
      <motorNumber>0</motorNumber>
      <rotorDragCoefficient>8.06428e-05</rotorDragCoefficient>
      <rollingMomentCoefficient>1e-06</rollingMomentCoefficient>
      <rotorVelocitySlowdownSim>10</rotorVelocitySlowdownSim>
      <motorType>velocity</motorType>
    </plugin>
    <plugin filename="gz-sim-multicopter-motor-model-system" name="gz::sim::systems::MulticopterMotorModel">
      <jointName>rotor_1_joint</jointName>
      <linkName>rotor_1</linkName>
      <turningDirection>ccw</turningDirection>
      <timeConstantUp>0.0125</timeConstantUp>
      <timeConstantDown>0.025</timeConstantDown>
      <maxRotVelocity>1000.0</maxRotVelocity>
      <motorConstant>8.54858e-06</motorConstant>
      <momentConstant>0.016</momentConstant>
      <commandSubTopic>command/motor_speed</commandSubTopic>
      <motorNumber>1</motorNumber>
      <rotorDragCoefficient>8.06428e-05</rotorDragCoefficient>
      <rollingMomentCoefficient>1e-06</rollingMomentCoefficient>
      <rotorVelocitySlowdownSim>10</rotorVelocitySlowdownSim>
      <motorType>velocity</motorType>
    </plugin>
    <plugin filename="gz-sim-multicopter-motor-model-system" name="gz::sim::systems::MulticopterMotorModel">
      <jointName>rotor_2_joint</jointName>
      <linkName>rotor_2</linkName>
      <turningDirection>cw</turningDirection>
      <timeConstantUp>0.0125</timeConstantUp>
      <timeConstantDown>0.025</timeConstantDown>
      <maxRotVelocity>1000.0</maxRotVelocity>
      <motorConstant>8.54858e-06</motorConstant>
      <momentConstant>0.016</momentConstant>
      <commandSubTopic>command/motor_speed</commandSubTopic>
      <motorNumber>2</motorNumber>
      <rotorDragCoefficient>8.06428e-05</rotorDragCoefficient>
      <rollingMomentCoefficient>1e-06</rollingMomentCoefficient>
      <rotorVelocitySlowdownSim>10</rotorVelocitySlowdownSim>
      <motorType>velocity</motorType>
    </plugin>
    <plugin filename="gz-sim-multicopter-motor-model-system" name="gz::sim::systems::MulticopterMotorModel">
      <jointName>rotor_3_joint</jointName>
      <linkName>rotor_3</linkName>
      <turningDirection>cw</turningDirection>
      <timeConstantUp>0.0125</timeConstantUp>
      <timeConstantDown>0.025</timeConstantDown>
      <maxRotVelocity>1000.0</maxRotVelocity>
      <motorConstant>8.54858e-06</motorConstant>
      <momentConstant>0.016</momentConstant>
      <commandSubTopic>command/motor_speed</commandSubTopic>
      <motorNumber>3</motorNumber>
      <rotorDragCoefficient>8.06428e-05</rotorDragCoefficient>
      <rollingMomentCoefficient>1e-06</rollingMomentCoefficient>
      <rotorVelocitySlowdownSim>10</rotorVelocitySlowdownSim>
      <motorType>velocity</motorType>
    </plugin>
    <link name="rovercopter_v3/SAG-PALET">
      <pose relative_to="base_link"> 0.01 -0.16 -0.0186 0 0 3.14 </pose>
      <inertial>
       <pose> 0 0 0 0 0 0 </pose>
        <mass> 0.015955 </mass>
        <inertia>
          <ixx>2.7437E-06</ixx>
          <ixy>-3.3049E-13</ixy>
          <ixz>-2.4624E-12</ixz>
          <iyy>2.7437E-06</iyy>
          <iyz>-1.8732E-13</iyz>
          <izz>3.0972E-06</izz>
        </inertia>
      </inertial>
      <visual name= "rovercopter_v3/sag_palet_visual">
        <pose> -0.22 -0.01 -0.095 0 0 0 </pose>
        <geometry>
          <mesh>
            <scale>0.001 0.001 0.001</scale>
            <uri>meshes/DETAY.STL</uri>
          </mesh>
        </geometry>
        <material>
          <ambient>0.02 0.02 0.02 1.0</ambient>
          <diffuse>0.02 0.02 0.02 1.0</diffuse>
          <specular>0.02 0.02 0.02 1.0</specular>
        </material>
      </visual>
      <!-- <collision name= "rovercopter_v3/sag_palet_collision">
        <geometry>
          <box>
            <size>0.40 0.02 0.2</size>
          </box>
        </geometry>
      </collision> -->
    </link>
    <joint name="rovercopter_v3/J_SAG-PALET" type="fixed">
      <parent> base_link </parent>
      <child> rovercopter_v3/SAG-PALET </child>
      <axis>
        <xyz> 1 0 0 </xyz>
        <limit>
          <lower>-1e+16</lower>
          <upper>1e+16</upper>
        </limit>
        <dynamics>
          <spring_reference>0</spring_reference>
          <spring_stiffness>0</spring_stiffness>
        </dynamics>
        <!-- <use_parent_model_frame>1</use_parent_model_frame> -->
      </axis>
    </joint>
    <link name="rovercopter_v3/SOL-PALET">
      <pose relative_to="base_link"> 0.01 0.16 -0.0186 0 0 3.14 </pose>
      <inertial>
        <pose> 0 0 0 0 0 0 </pose>
        <mass> 0.015955 </mass>
        <inertia>
          <ixx>2.7437E-06</ixx>
          <ixy>-3.3049E-13</ixy>
          <ixz>-2.4624E-12</ixz>
          <iyy>2.7437E-06</iyy>
          <iyz>-1.8732E-13</iyz>
          <izz>3.0972E-06</izz>
        </inertia>
      </inertial>
      <visual name= "rovercopter_v3/sol_palet_visual">
        <pose > -0.22 -0.01 -0.095 0 0 0 </pose>
        <geometry>
          <mesh>
            <scale>0.001 0.001 0.001</scale>
            <uri>meshes/DETAY.STL</uri>
          </mesh>
        </geometry>
        <material>
          <ambient>0.02 0.02 0.02 1.0</ambient>
          <diffuse>0.02 0.02 0.02 1.0</diffuse>
          <specular>0.02 0.02 0.02 1.0</specular>
        </material>
      </visual>
      <!-- <collision name= "rovercopter_v3/sol_palet_collision">
        <geometry>
          <box>
              <size>0.40 0.02 0.2</size>
          </box>
        </geometry>
      </collision> -->
    </link>
    <joint name="rovercopter_v3/J_SOL-PALET" type="fixed">
      <parent> base_link </parent>
      <child> rovercopter_v3/SOL-PALET </child>
      <axis>
        <xyz> 1 0 0 </xyz>
        <limit>
          <lower>-1e+16</lower>
          <upper>1e+16</upper>
        </limit>
        <dynamics>
          <spring_reference>0</spring_reference>
          <spring_stiffness>0</spring_stiffness>
        </dynamics>
        <!-- <use_parent_model_frame>1</use_parent_model_frame> -->
      </axis>
    </joint>
    <plugin name="gz::sim::systems::TrackedVehicle" filename="gz-sim-tracked-vehicle-system">
      <body>base_link</body>
      <left_track><link>rovercopter_v3/SOL-PALET</link></left_track>
      <right_track><link>rovercopter_v3/SAG-PALET</link></right_track>
      <tracks_separation>0.3</tracks_separation>
      <tracks_height>0.01</tracks_height>
      <steering_efficiency>0.2</steering_efficiency>
      <!-- <debug> 1 </debug> -->
    </plugin>
    <plugin name="gz::sim::systems::TrackController" filename="gz-sim-track-controller-system">
      <link>rovercopter_v3/SOL-PALET</link>
      <min_velocity>-1.0</min_velocity>
      <max_velocity>1.0</max_velocity>
      <!-- <debug> 1 </debug> -->
    </plugin>
    <plugin name="gz::sim::systems::TrackController" filename="gz-sim-track-controller-system">
      <link>rovercopter_v3/SAG-PALET</link>
      <min_velocity>-1.0</min_velocity>
      <max_velocity>1.0</max_velocity>
      <!-- <debug> 1 </debug> -->
    </plugin>
  </model>
</sdf>
